Workbook

Sheet Executive Summary
B2: Indian Patent Portfolio — Client & Due Date Analysis
B3: Snapshot report generated from filing / RQ (Request for Examination) data. RQ deadline figures recalculate live against today's date.
B5: Total Cases | D5: Unique Clients | F5: Pending RQ (Active) | H5: Overdue RQ
B6: =COUNTA(Data!B2:B6232) -> 6052 | D6: =COUNTA('Client Summary'!A2:A607) -> 606 | F6: =SUM('Client Summary'!J2:J607) -> 1227 | H6: =SUM('Client Summary'!K2:K607) -> 788
B10: RQ Urgency (Active Cases) | E10: Top 10 Clients — Overdue + Due-Soon RQ Filings
B11: Urgency | C11: Count | E11: Client Name | F11: Overdue | G11: Due >=90d | H11: Next RQ Due
B12: OVERDUE | C12: =SUMPRODUCT(('Pending RQ Deadlines'!$J$2:$J$1271="OVERDUE")*('Pending RQ Deadlines'!$K$2:$K$1271="Yes")) -> 747 | E12: =IF(LARGE('Client Summary'!$N$2:$N$607,1)<=0,"",INDEX('Client Summary'!$A$2:$A$607,MATCH(LARGE('Client Summary'!$N$2:$N$607,1),'Client Summary'!$N$2:$N$607,0))) -> ZUMUTOR BIOLOGICS, INC. | F12: =IF(LARGE('Client Summary'!$N$2:$N$607,1)<=0,"",INDEX('Client Summary'!$K$2:$K$607,MATCH(LARGE('Client Summary'!$N$2:$N$607,1),'Client Summary'!$N$2:$N$607,0))) -> 1 | G12: =IF(LARGE('Client Summary'!$N$2:$N$607,1)<=0,"",INDEX('Client Summary'!$L$2:$L$607,MATCH(LARGE('Client Summary'!$N$2:$N$607,1),'Client Summary'!$N$2:$N$607,0))) -> 1 | H12: =IF(LARGE('Client Summary'!$N$2:$N$607,1)<=0,"",INDEX('Client Summary'!$M$2:$M$607,MATCH(LARGE('Client Summary'!$N$2:$N$607,1),'Client Summary'!$N$2:$N$607,0)))
B13: DUE <=30 DAYS | C13: =SUMPRODUCT(('Pending RQ Deadlines'!$J$2:$J$1271="DUE <=30 DAYS")*('Pending RQ Deadlines'!$K$2:$K$1271="Yes")) -> 3 | E13: =IF(LARGE('Client Summary'!$N$2:$N$607,2)<=0,"",INDEX('Client Summary'!$A$2:$A$607,MATCH(LARGE('Client Summary'!$N$2:$N$607,2),'Client Summary'!$N$2:$N$607,0))) -> 3B PHARMACEUTICALS GMBH | F13: =IF(LARGE('Client Summary'!$N$2:$N$607,2)<=0,"",INDEX('Client Summary'!$K$2:$K$607,MATCH(LARGE('Client Summary'!$N$2:$N$607,2),'Client Summary'!$N$2:$N$607,0))) -> 0 | G13: =IF(LARGE('Client Summary'!$N$2:$N$607,2)<=0,"",INDEX('Client Summary'!$L$2:$L$607,MATCH(LARGE('Client Summary'!$N$2:$N$607,2),'Client Summary'!$N$2:$N$607,0))) -> 0 | H13: =IF(LARGE('Client Summary'!$N$2:$N$607,2)<=0,"",INDEX('Client Summary'!$M$2:$M$607,MATCH(LARGE('Client Summary'!$N$2:$N$607,2),'Client Summary'!$N$2:$N$607,0)))
B14: DUE <=90 DAYS | C14: =SUMPRODUCT(('Pending RQ Deadlines'!$J$2:$J$1271="DUE <=90 DAYS")*('Pending RQ Deadlines'!$K$2:$K$1271="Yes")) -> 1 | E14: =IF(LARGE('Client Summary'!$N$2:$N$607,3)<=0,"",INDEX('Client Summary'!$A$2:$A$607,MATCH(LARGE('Client Summary'!$N$2:$N$607,3),'Client Summary'!$N$2:$N$607,0))) -> ACTEGA GmbH | F14: =IF(LARGE('Client Summary'!$N$2:$N$607,3)<=0,"",INDEX('Client Summary'!$K$2:$K$607,MATCH(LARGE('Client Summary'!$N$2:$N$607,3),'Client Summary'!$N$2:$N$607,0))) -> 0 | G14: =IF(LARGE('Client Summary'!$N$2:$N$607,3)<=0,"",INDEX('Client Summary'!$L$2:$L$607,MATCH(LARGE('Client Summary'!$N$2:$N$607,3),'Client Summary'!$N$2:$N$607,0))) -> 0 | H14: =IF(LARGE('Client Summary'!$N$2:$N$607,3)<=0,"",INDEX('Client Summary'!$M$2:$M$607,MATCH(LARGE('Client Summary'!$N$2:$N$607,3),'Client Summary'!$N$2:$N$607,0)))
B15: UPCOMING | C15: =SUMPRODUCT(('Pending RQ Deadlines'!$J$2:$J$1271="UPCOMING")*('Pending RQ Deadlines'!$K$2:$K$1271="Yes")) -> 467 | E15: =IF(LARGE('Client Summary'!$N$2:$N$607,4)<=0,"",INDEX('Client Summary'!$A$2:$A$607,MATCH(LARGE('Client Summary'!$N$2:$N$607,4),'Client Summary'!$N$2:$N$607,0))) -> ADLER POLLOCK & SHEEHAN P.C. | F15: =IF(LARGE('Client Summary'!$N$2:$N$607,4)<=0,"",INDEX('Client Summary'!$K$2:$K$607,MATCH(LARGE('Client Summary'!$N$2:$N$607,4),'Client Summary'!$N$2:$N$607,0))) -> 0 | G15: =IF(LARGE('Client Summary'!$N$2:$N$607,4)<=0,"",INDEX('Client Summary'!$L$2:$L$607,MATCH(LARGE('Client Summary'!$N$2:$N$607,4),'Client Summary'!$N$2:$N$607,0))) -> 0 | H15: =IF(LARGE('Client Summary'!$N$2:$N$607,4)<=0,"",INDEX('Client Summary'!$M$2:$M$607,MATCH(LARGE('Client Summary'!$N$2:$N$607,4),'Client Summary'!$N$2:$N$607,0)))
E16: =IF(LARGE('Client Summary'!$N$2:$N$607,5)<=0,"",INDEX('Client Summary'!$A$2:$A$607,MATCH(LARGE('Client Summary'!$N$2:$N$607,5),'Client Summary'!$N$2:$N$607,0))) -> ZENITH PATENT & LAW FIRM | F16: =IF(LARGE('Client Summary'!$N$2:$N$607,5)<=0,"",INDEX('Client Summary'!$K$2:$K$607,MATCH(LARGE('Client Summary'!$N$2:$N$607,5),'Client Summary'!$N$2:$N$607,0))) -> 0 | G16: =IF(LARGE('Client Summary'!$N$2:$N$607,5)<=0,"",INDEX('Client Summary'!$L$2:$L$607,MATCH(LARGE('Client Summary'!$N$2:$N$607,5),'Client Summary'!$N$2:$N$607,0))) -> 0 | H16: =IF(LARGE('Client Summary'!$N$2:$N$607,5)<=0,"",INDEX('Client Summary'!$M$2:$M$607,MATCH(LARGE('Client Summary'!$N$2:$N$607,5),'Client Summary'!$N$2:$N$607,0)))
E17: =IF(LARGE('Client Summary'!$N$2:$N$607,6)<=0,"",INDEX('Client Summary'!$A$2:$A$607,MATCH(LARGE('Client Summary'!$N$2:$N$607,6),'Client Summary'!$N$2:$N$607,0))) -> AGTEKS ORME VE TEKSTIL | F17: =IF(LARGE('Client Summary'!$N$2:$N$607,6)<=0,"",INDEX('Client Summary'!$K$2:$K$607,MATCH(LARGE('Client Summary'!$N$2:$N$607,6),'Client Summary'!$N$2:$N$607,0))) -> 0 | G17: =IF(LARGE('Client Summary'!$N$2:$N$607,6)<=0,"",INDEX('Client Summary'!$L$2:$L$607,MATCH(LARGE('Client Summary'!$N$2:$N$607,6),'Client Summary'!$N$2:$N$607,0))) -> 0 | H17: =IF(LARGE('Client Summary'!$N$2:$N$607,6)<=0,"",INDEX('Client Summary'!$M$2:$M$607,MATCH(LARGE('Client Summary'!$N$2:$N$607,6),'Client Summary'!$N$2:$N$607,0)))
E18: =IF(LARGE('Client Summary'!$N$2:$N$607,7)<=0,"",INDEX('Client Summary'!$A$2:$A$607,MATCH(LARGE('Client Summary'!$N$2:$N$607,7),'Client Summary'!$N$2:$N$607,0))) -> AHMEDABAD TEXTILE IND. RESEARCH ASSOCIATION | F18: =IF(LARGE('Client Summary'!$N$2:$N$607,7)<=0,"",INDEX('Client Summary'!$K$2:$K$607,MATCH(LARGE('Client Summary'!$N$2:$N$607,7),'Client Summary'!$N$2:$N$607,0))) -> 1 | G18: =IF(LARGE('Client Summary'!$N$2:$N$607,7)<=0,"",INDEX('Client Summary'!$L$2:$L$607,MATCH(LARGE('Client Summary'!$N$2:$N$607,7),'Client Summary'!$N$2:$N$607,0))) -> 1 | H18: =IF(LARGE('Client Summary'!$N$2:$N$607,7)<=0,"",INDEX('Client Summary'!$M$2:$M$607,MATCH(LARGE('Client Summary'!$N$2:$N$607,7),'Client Summary'!$N$2:$N$607,0)))
E19: =IF(LARGE('Client Summary'!$N$2:$N$607,8)<=0,"",INDEX('Client Summary'!$A$2:$A$607,MATCH(LARGE('Client Summary'!$N$2:$N$607,8),'Client Summary'!$N$2:$N$607,0))) -> AIG HOSPITALS | F19: =IF(LARGE('Client Summary'!$N$2:$N$607,8)<=0,"",INDEX('Client Summary'!$K$2:$K$607,MATCH(LARGE('Client Summary'!$N$2:$N$607,8),'Client Summary'!$N$2:$N$607,0))) -> 1 | G19: =IF(LARGE('Client Summary'!$N$2:$N$607,8)<=0,"",INDEX('Client Summary'!$L$2:$L$607,MATCH(LARGE('Client Summary'!$N$2:$N$607,8),'Client Summary'!$N$2:$N$607,0))) -> 1 | H19: =IF(LARGE('Client Summary'!$N$2:$N$607,8)<=0,"",INDEX('Client Summary'!$M$2:$M$607,MATCH(LARGE('Client Summary'!$N$2:$N$607,8),'Client Summary'!$N$2:$N$607,0)))
E20: =IF(LARGE('Client Summary'!$N$2:$N$607,9)<=0,"",INDEX('Client Summary'!$A$2:$A$607,MATCH(LARGE('Client Summary'!$N$2:$N$607,9),'Client Summary'!$N$2:$N$607,0))) -> AISIN CORPORATION | F20: =IF(LARGE('Client Summary'!$N$2:$N$607,9)<=0,"",INDEX('Client Summary'!$K$2:$K$607,MATCH(LARGE('Client Summary'!$N$2:$N$607,9),'Client Summary'!$N$2:$N$607,0))) -> 1 | G20: =IF(LARGE('Client Summary'!$N$2:$N$607,9)<=0,"",INDEX('Client Summary'!$L$2:$L$607,MATCH(LARGE('Client Summary'!$N$2:$N$607,9),'Client Summary'!$N$2:$N$607,0))) -> 1 | H20: =IF(LARGE('Client Summary'!$N$2:$N$607,9)<=0,"",INDEX('Client Summary'!$M$2:$M$607,MATCH(LARGE('Client Summary'!$N$2:$N$607,9),'Client Summary'!$N$2:$N$607,0)))
E21: =IF(LARGE('Client Summary'!$N$2:$N$607,10)<=0,"",INDEX('Client Summary'!$A$2:$A$607,MATCH(LARGE('Client Summary'!$N$2:$N$607,10),'Client Summary'!$N$2:$N$607,0))) -> YOKOHAMA SIGMA IP LAW FIRM | F21: =IF(LARGE('Client Summary'!$N$2:$N$607,10)<=0,"",INDEX('Client Summary'!$K$2:$K$607,MATCH(LARGE('Client Summary'!$N$2:$N$607,10),'Client Summary'!$N$2:$N$607,0))) -> 0 | G21: =IF(LARGE('Client Summary'!$N$2:$N$607,10)<=0,"",INDEX('Client Summary'!$L$2:$L$607,MATCH(LARGE('Client Summary'!$N$2:$N$607,10),'Client Summary'!$N$2:$N$607,0))) -> 0 | H21: =IF(LARGE('Client Summary'!$N$2:$N$607,10)<=0,"",INDEX('Client Summary'!$M$2:$M$607,MATCH(LARGE('Client Summary'!$N$2:$N$607,10),'Client Summary'!$N$2:$N$607,0)))
B22: Notes:
B23: • RQ (Request for Examination) must be filed within 31 months of the priority/filing date under the Indian Patents Act.
B24: • 'Pending RQ (Active)' excludes cases marked Abandoned / Closed / Merged, where no RQ action is required.
B25: • 'Days Remaining' and urgency flags on the Pending RQ Deadlines sheet use TODAY() and update automatically when reopened.
B26: • Client Summary sheet lists all 606 clients; sort/filter by Overdue RQ or Due within 90 Days to prioritise outreach.

Sheet Client Summary
A1: Client Name | B1: Total Cases | C1: RFE Filed | D1: Provisional Filed | E1: Complete Filed | F1: Application Filed | G1: Under Examination | H1: Granted | I1: Abandoned/Closed/Merged | J1: Pending RQ (Active) | K1: Overdue RQ | L1: Due within 90 Days | M1: Next RQ Due Date | N1: Urgency Score (for ranking)
A2: QUALCOMM INCORPORATED | B2: =COUNTIF(Data!$D$2:$D$6232,A2) -> 907 | C2: =COUNTIFS(Data!$D$2:$D$6232,A2,Data!$R$2:$R$6232,"RFE FILED") -> 808 | D2: =COUNTIFS(Data!$D$2:$D$6232,A2,Data!$R$2:$R$6232,"PROVISIONAL FILED") -> 90 | E2: =COUNTIFS(Data!$D$2:$D$6232,A2,Data!$R$2:$R$6232,"COMPLETE FILED") -> 1 | F2: =COUNTIFS(Data!$D$2:$D$6232,A2,Data!$R$2:$R$6232,"APPLICATION FILED") -> 0 | G2: =COUNTIFS(Data!$D$2:$D$6232,A2,Data!$R$2:$R$6232,"UNDER EXAMINATION") -> 5 | H2: =COUNTIFS(Data!$D$2:$D$6232,A2,Data!$R$2:$R$6232,"GRANTED") -> 0 | I2: =SUMPRODUCT((Data!$D$2:$D$6232=A2)*((Data!$R$2:$R$6232="ABANDONED")+(Data!$R$2:$R$6232="CLOSED")+(Data!$R$2:$R$6232="MERGED"))) -> 2 | J2: =COUNTIFS('Pending RQ Deadlines'!$C$2:$C$1271,A2,'Pending RQ Deadlines'!$K$2:$K$1271,"Yes") -> 91 | K2: =COUNTIFS('Pending RQ Deadlines'!$C$2:$C$1271,A2,'Pending RQ Deadlines'!$J$2:$J$1271,"OVERDUE") -> 62 | L2: =SUMPRODUCT(('Pending RQ Deadlines'!$C$2:$C$1271=A2)*('Pending RQ Deadlines'!$J$2:$J$1271<>"UPCOMING")*('Pending RQ Deadlines'!$K$2:$K$1271="Yes")) -> 62 | M2: =IFERROR(_xludf.minifs('Pending RQ Deadlines'!$G$2:$G$1271,'Pending RQ Deadlines'!$C$2:$C$1271,A2),"") | N2: =ROW()-L2+K2/100 -> -59.38
A3: PHIL & ONZI | B3: =COUNTIF(Data!$D$2:$D$6232,A3) -> 258 | C3: =COUNTIFS(Data!$D$2:$D$6232,A3,Data!$R$2:$R$6232,"RFE FILED") -> 258 | D3: =COUNTIFS(Data!$D$2:$D$6232,A3,Data!$R$2:$R$6232,"PROVISIONAL FILED") -> 0 | E3: =COUNTIFS(Data!$D$2:$D$6232,A3,Data!$R$2:$R$6232,"COMPLETE FILED") -> 0 | F3: =COUNTIFS(Data!$D$2:$D$6232,A3,Data!$R$2:$R$6232,"APPLICATION FILED") -> 0 | G3: =COUNTIFS(Data!$D$2:$D$6232,A3,Data!$R$2:$R$6232,"UNDER EXAMINATION") -> 0 | H3: =COUNTIFS(Data!$D$2:$D$6232,A3,Data!$R$2:$R$6232,"GRANTED") -> 0 | I3: =SUMPRODUCT((Data!$D$2:$D$6232=A3)*((Data!$R$2:$R$6232="ABANDONED")+(Data!$R$2:$R$6232="CLOSED")+(Data!$R$2:$R$6232="MERGED"))) -> 0 | J3: =COUNTIFS('Pending RQ Deadlines'!$C$2:$C$1271,A3,'Pending RQ Deadlines'!$K$2:$K$1271,"Yes") -> 0 | K3: =COUNTIFS('Pending RQ Deadlines'!$C$2:$C$1271,A3,'Pending RQ Deadlines'!$J$2:$J$1271,"OVERDUE") -> 0 | L3: =SUMPRODUCT(('Pending RQ Deadlines'!$C$2:$C$1271=A3)*('Pending RQ Deadlines'!$J$2:$J$1271<>"UPCOMING")*('Pending RQ Deadlines'!$K$2:$K$1271="Yes")) -> 0 | M3: =IFERROR(_xludf.minifs('Pending RQ Deadlines'!$G$2:$G$1271,'Pending RQ Deadlines'!$C$2:$C$1271,A3),"") | N3: =ROW()-L3+K3/100 -> 3
A4: Samsung R&D Institute India-Bangalore Pvt. Ltd. | B4: =COUNTIF(Data!$D$2:$D$6232,A4) -> 185 | C4: =COUNTIFS(Data!$D$2:$D$6232,A4,Data!$R$2:$R$6232,"RFE FILED") -> 65 | D4: =COUNTIFS(Data!$D$2:$D$6232,A4,Data!$R$2:$R$6232,"PROVISIONAL FILED") -> 117 | E4: =COUNTIFS(Data!$D$2:$D$6232,A4,Data!$R$2:$R$6232,"COMPLETE FILED") -> 0 | F4: =COUNTIFS(Data!$D$2:$D$6232,A4,Data!$R$2:$R$6232,"APPLICATION FILED") -> 0 | G4: =COUNTIFS(Data!$D$2:$D$6232,A4,Data!$R$2:$R$6232,"UNDER EXAMINATION") -> 0 | H4: =COUNTIFS(Data!$D$2:$D$6232,A4,Data!$R$2:$R$6232,"GRANTED") -> 0 | I4: =SUMPRODUCT((Data!$D$2:$D$6232=A4)*((Data!$R$2:$R$6232="ABANDONED")+(Data!$R$2:$R$6232="CLOSED")+(Data!$R$2:$R$6232="MERGED"))) -> 3 | J4: =COUNTIFS('Pending RQ Deadlines'!$C$2:$C$1271,A4,'Pending RQ Deadlines'!$K$2:$K$1271,"Yes") -> 117 | K4: =COUNTIFS('Pending RQ Deadlines'!$C$2:$C$1271,A4,'Pending RQ Deadlines'!$J$2:$J$1271,"OVERDUE") -> 76 | L4: =SUMPRODUCT(('Pending RQ Deadlines'!$C$2:$C$1271=A4)*('Pending RQ Deadlines'!$J$2:$J$1271<>"UPCOMING")*('Pending RQ Deadlines'!$K$2:$K$1271="Yes")) -> 74 | M4: =IFERROR(_xludf.minifs('Pending RQ Deadlines'!$G$2:$G$1271,'Pending RQ Deadlines'!$C$2:$C$1271,A4),"") | N4: =ROW()-L4+K4/100 -> -69.24
A5: BAE, KIM & LEE IP GROUP | B5: =COUNTIF(Data!$D$2:$D$6232,A5) -> 184 | C5: =COUNTIFS(Data!$D$2:$D$6232,A5,Data!$R$2:$R$6232,"RFE FILED") -> 184 | D5: =COUNTIFS(Data!$D$2:$D$6232,A5,Data!$R$2:$R$6232,"PROVISIONAL FILED") -> 0 | E5: =COUNTIFS(Data!$D$2:$D$6232,A5,Data!$R$2:$R$6232,"COMPLETE FILED") -> 0 | F5: =COUNTIFS(Data!$D$2:$D$6232,A5,Data!$R$2:$R$6232,"APPLICATION FILED") -> 0 | G5: =COUNTIFS(Data!$D$2:$D$6232,A5,Data!$R$2:$R$6232,"UNDER EXAMINATION") -> 0 | H5: =COUNTIFS(Data!$D$2:$D$6232,A5,Data!$R$2:$R$6232,"GRANTED") -> 0 | I5: =SUMPRODUCT((Data!$D$2:$D$6232=A5)*((Data!$R$2:$R$6232="ABANDONED")+(Data!$R$2:$R$6232="CLOSED")+(Data!$R$2:$R$6232="MERGED"))) -> 0 | J5: =COUNTIFS('Pending RQ Deadlines'!$C$2:$C$1271,A5,'Pending RQ Deadlines'!$K$2:$K$1271,"Yes") -> 0 | K5: =COUNTIFS('Pending RQ Deadlines'!$C$2:$C$1271,A5,'Pending RQ Deadlines'!$J$2:$J$1271,"OVERDUE") -> 0 | L5: =SUMPRODUCT(('Pending RQ Deadlines'!$C$2:$C$1271=A5)*('Pending RQ Deadlines'!$J$2:$J$1271<>"UPCOMING")*('Pending RQ Deadlines'!$K$2:$K$1271="Yes")) -> 0 | M5: =IFERROR(_xludf.minifs('Pending RQ Deadlines'!$G$2:$G$1271,'Pending RQ Deadlines'!$C$2:$C$1271,A5),"") | N5: =ROW()-L5+K5/100 -> 5
A6: CISCO TECHNOLOGY, INC. | B6: =COUNTIF(Data!$D$2:$D$6232,A6) -> 161 | C6: =COUNTIFS(Data!$D$2:$D$6232,A6,Data!$R$2:$R$6232,"RFE FILED") -> 120 | D6: =COUNTIFS(Data!$D$2:$D$6232,A6,Data!$R$2:$R$6232,"PROVISIONAL FILED") -> 37 | E6: =COUNTIFS(Data!$D$2:$D$6232,A6,Data!$R$2:$R$6232,"COMPLETE FILED") -> 0 | F6: =COUNTIFS(Data!$D$2:$D$6232,A6,Data!$R$2:$R$6232,"APPLICATION FILED") -> 0 | G6: =COUNTIFS(Data!$D$2:$D$6232,A6,Data!$R$2:$R$6232,"UNDER EXAMINATION") -> 1 | H6: =COUNTIFS(Data!$D$2:$D$6232,A6,Data!$R$2:$R$6232,"GRANTED") -> 0 | I6: =SUMPRODUCT((Data!$D$2:$D$6232=A6)*((Data!$R$2:$R$6232="ABANDONED")+(Data!$R$2:$R$6232="CLOSED")+(Data!$R$2:$R$6232="MERGED"))) -> 3 | J6: =COUNTIFS('Pending RQ Deadlines'!$C$2:$C$1271,A6,'Pending RQ Deadlines'!$K$2:$K$1271,"Yes") -> 37 | K6: =COUNTIFS('Pending RQ Deadlines'!$C$2:$C$1271,A6,'Pending RQ Deadlines'!$J$2:$J$1271,"OVERDUE") -> 27 | L6: =SUMPRODUCT(('Pending RQ Deadlines'!$C$2:$C$1271=A6)*('Pending RQ Deadlines'!$J$2:$J$1271<>"UPCOMING")*('Pending RQ Deadlines'!$K$2:$K$1271="Yes")) -> 26 | M6: =IFERROR(_xludf.minifs('Pending RQ Deadlines'!$G$2:$G$1271,'Pending RQ Deadlines'!$C$2:$C$1271,A6),"") | N6: =ROW()-L6+K6/100 -> -19.73
A7: IBM CORPORATION | B7: =COUNTIF(Data!$D$2:$D$6232,A7) -> 136 | C7: =COUNTIFS(Data!$D$2:$D$6232,A7,Data!$R$2:$R$6232,"RFE FILED") -> 129 | D7: =COUNTIFS(Data!$D$2:$D$6232,A7,Data!$R$2:$R$6232,"PROVISIONAL FILED") -> 0 | E7: =COUNTIFS(Data!$D$2:$D$6232,A7,Data!$R$2:$R$6232,"COMPLETE FILED") -> 0 | F7: =COUNTIFS(Data!$D$2:$D$6232,A7,Data!$R$2:$R$6232,"APPLICATION FILED") -> 0 | G7: =COUNTIFS(Data!$D$2:$D$6232,A7,Data!$R$2:$R$6232,"UNDER EXAMINATION") -> 5 | H7: =COUNTIFS(Data!$D$2:$D$6232,A7,Data!$R$2:$R$6232,"GRANTED") -> 0 | I7: =SUMPRODUCT((Data!$D$2:$D$6232=A7)*((Data!$R$2:$R$6232="ABANDONED")+(Data!$R$2:$R$6232="CLOSED")+(Data!$R$2:$R$6232="MERGED"))) -> 0 | J7: =COUNTIFS('Pending RQ Deadlines'!$C$2:$C$1271,A7,'Pending RQ Deadlines'!$K$2:$K$1271,"Yes") -> 0 | K7: =COUNTIFS('Pending RQ Deadlines'!$C$2:$C$1271,A7,'Pending RQ Deadlines'!$J$2:$J$1271,"OVERDUE") -> 0 | L7: =SUMPRODUCT(('Pending RQ Deadlines'!$C$2:$C$1271=A7)*('Pending RQ Deadlines'!$J$2:$J$1271<>"UPCOMING")*('Pending RQ Deadlines'!$K$2:$K$1271="Yes")) -> 0 | M7: =IFERROR(_xludf.minifs('Pending RQ Deadlines'!$G$2:$G$1271,'Pending RQ Deadlines'!$C$2:$C$1271,A7),"") | N7: =ROW()-L7+K7/100 -> 7
A8: MERCEDES-BENZ INTELLECTUAL PROPERTY GMBH & CO KG | B8: =COUNTIF(Data!$D$2:$D$6232,A8) -> 135 | C8: =COUNTIFS(Data!$D$2:$D$6232,A8,Data!$R$2:$R$6232,"RFE FILED") -> 0 | D8: =COUNTIFS(Data!$D$2:$D$6232,A8,Data!$R$2:$R$6232,"PROVISIONAL FILED") -> 0 | E8: =COUNTIFS(Data!$D$2:$D$6232,A8,Data!$R$2:$R$6232,"COMPLETE FILED") -> 135 | F8: =COUNTIFS(Data!$D$2:$D$6232,A8,Data!$R$2:$R$6232,"APPLICATION FILED") -> 0 | G8: =COUNTIFS(Data!$D$2:$D$6232,A8,Data!$R$2:$R$6232,"UNDER EXAMINATION") -> 0 | H8: =COUNTIFS(Data!$D$2:$D$6232,A8,Data!$R$2:$R$6232,"GRANTED") -> 0 | I8: =SUMPRODUCT((Data!$D$2:$D$6232=A8)*((Data!$R$2:$R$6232="ABANDONED")+(Data!$R$2:$R$6232="CLOSED")+(Data!$R$2:$R$6232="MERGED"))) -> 0 | J8: =COUNTIFS('Pending RQ Deadlines'!$C$2:$C$1271,A8,'Pending RQ Deadlines'!$K$2:$K$1271,"Yes") -> 135 | K8: =COUNTIFS('Pending RQ Deadlines'!$C$2:$C$1271,A8,'Pending RQ Deadlines'!$J$2:$J$1271,"OVERDUE") -> 93 | L8: =SUMPRODUCT(('Pending RQ Deadlines'!$C$2:$C$1271=A8)*('Pending RQ Deadlines'!$J$2:$J$1271<>"UPCOMING")*('Pending RQ Deadlines'!$K$2:$K$1271="Yes")) -> 93 | M8: =IFERROR(_xludf.minifs('Pending RQ Deadlines'!$G$2:$G$1271,'Pending RQ Deadlines'!$C$2:$C$1271,A8),"") | N8: =ROW()-L8+K8/100 -> -84.07
A9: TATA STEEL LIMITED | B9: =COUNTIF(Data!$D$2:$D$6232,A9) -> 134 | C9: =COUNTIFS(Data!$D$2:$D$6232,A9,Data!$R$2:$R$6232,"RFE FILED") -> 134 | D9: =COUNTIFS(Data!$D$2:$D$6232,A9,Data!$R$2:$R$6232,"PROVISIONAL FILED") -> 0 | E9: =COUNTIFS(Data!$D$2:$D$6232,A9,Data!$R$2:$R$6232,"COMPLETE FILED") -> 0 | F9: =COUNTIFS(Data!$D$2:$D$6232,A9,Data!$R$2:$R$6232,"APPLICATION FILED") -> 0 | G9: =COUNTIFS(Data!$D$2:$D$6232,A9,Data!$R$2:$R$6232,"UNDER EXAMINATION") -> 0 | H9: =COUNTIFS(Data!$D$2:$D$6232,A9,Data!$R$2:$R$6232,"GRANTED") -> 0 | I9: =SUMPRODUCT((Data!$D$2:$D$6232=A9)*((Data!$R$2:$R$6232="ABANDONED")+(Data!$R$2:$R$6232="CLOSED")+(Data!$R$2:$R$6232="MERGED"))) -> 0 | J9: =COUNTIFS('Pending RQ Deadlines'!$C$2:$C$1271,A9,'Pending RQ Deadlines'!$K$2:$K$1271,"Yes") -> 0 | K9: =COUNTIFS('Pending RQ Deadlines'!$C$2:$C$1271,A9,'Pending RQ Deadlines'!$J$2:$J$1271,"OVERDUE") -> 0 | L9: =SUMPRODUCT(('Pending RQ Deadlines'!$C$2:$C$1271=A9)*('Pending RQ Deadlines'!$J$2:$J$1271<>"UPCOMING")*('Pending RQ Deadlines'!$K$2:$K$1271="Yes")) -> 0 | M9: =IFERROR(_xludf.minifs('Pending RQ Deadlines'!$G$2:$G$1271,'Pending RQ Deadlines'!$C$2:$C$1271,A9),"") | N9: =ROW()-L9+K9/100 -> 9
A10: ABB SWITZERLAND LTD. | B10: =COUNTIF(Data!$D$2:$D$6232,A10) -> 127 | C10: =COUNTIFS(Data!$D$2:$D$6232,A10,Data!$R$2:$R$6232,"RFE FILED") -> 124 | D10: =COUNTIFS(Data!$D$2:$D$6232,A10,Data!$R$2:$R$6232,"PROVISIONAL FILED") -> 2 | E10: =COUNTIFS(Data!$D$2:$D$6232,A10,Data!$R$2:$R$6232,"COMPLETE FILED") -> 0 | F10: =COUNTIFS(Data!$D$2:$D$6232,A10,Data!$R$2:$R$6232,"APPLICATION FILED") -> 0 | G10: =COUNTIFS(Data!$D$2:$D$6232,A10,Data!$R$2:$R$6232,"UNDER EXAMINATION") -> 0 | H10: =COUNTIFS(Data!$D$2:$D$6232,A10,Data!$R$2:$R$6232,"GRANTED") -> 0 | I10: =SUMPRODUCT((Data!$D$2:$D$6232=A10)*((Data!$R$2:$R$6232="ABANDONED")+(Data!$R$2:$R$6232="CLOSED")+(Data!$R$2:$R$6232="MERGED"))) -> 0 | J10: =COUNTIFS('Pending RQ Deadlines'!$C$2:$C$1271,A10,'Pending RQ Deadlines'!$K$2:$K$1271,"Yes") -> 3 | K10: =COUNTIFS('Pending RQ Deadlines'!$C$2:$C$1271,A10,'Pending RQ Deadlines'!$J$2:$J$1271,"OVERDUE") -> 0 | L10: =SUMPRODUCT(('Pending RQ Deadlines'!$C$2:$C$1271=A10)*('Pending RQ Deadlines'!$J$2:$J$1271<>"UPCOMING")*('Pending RQ Deadlines'!$K$2:$K$1271="Yes")) -> 0 | M10: =IFERROR(_xludf.minifs('Pending RQ Deadlines'!$G$2:$G$1271,'Pending RQ Deadlines'!$C$2:$C$1271,A10),"") | N10: =ROW()-L10+K10/100 -> 10
A11: FOLEY & LARDNER LLP | B11: =COUNTIF(Data!$D$2:$D$6232,A11) -> 111 | C11: =COUNTIFS(Data!$D$2:$D$6232,A11,Data!$R$2:$R$6232,"RFE FILED") -> 63 | D11: =COUNTIFS(Data!$D$2:$D$6232,A11,Data!$R$2:$R$6232,"PROVISIONAL FILED") -> 36 | E11: =COUNTIFS(Data!$D$2:$D$6232,A11,Data!$R$2:$R$6232,"COMPLETE FILED") -> 5 | F11: =COUNTIFS(Data!$D$2:$D$6232,A11,Data!$R$2:$R$6232,"APPLICATION FILED") -> 3 | G11: =COUNTIFS(Data!$D$2:$D$6232,A11,Data!$R$2:$R$6232,"UNDER EXAMINATION") -> 0 | H11: =COUNTIFS(Data!$D$2:$D$6232,A11,Data!$R$2:$R$6232,"GRANTED") -> 0 | I11: =SUMPRODUCT((Data!$D$2:$D$6232=A11)*((Data!$R$2:$R$6232="ABANDONED")+(Data!$R$2:$R$6232="CLOSED")+(Data!$R$2:$R$6232="MERGED"))) -> 3 | J11: =COUNTIFS('Pending RQ Deadlines'!$C$2:$C$1271,A11,'Pending RQ Deadlines'!$K$2:$K$1271,"Yes") -> 44 | K11: =COUNTIFS('Pending RQ Deadlines'!$C$2:$C$1271,A11,'Pending RQ Deadlines'!$J$2:$J$1271,"OVERDUE") -> 32 | L11: =SUMPRODUCT(('Pending RQ Deadlines'!$C$2:$C$1271=A11)*('Pending RQ Deadlines'!$J$2:$J$1271<>"UPCOMING")*('Pending RQ Deadlines'!$K$2:$K$1271="Yes")) -> 30 | M11: =IFERROR(_xludf.minifs('Pending RQ Deadlines'!$G$2:$G$1271,'Pending RQ Deadlines'!$C$2:$C$1271,A11),"") | N11: =ROW()-L11+K11/100 -> -18.68
A12: TATA MOTORS PASSENGER VEHICLES LIMITED | B12: =COUNTIF(Data!$D$2:$D$6232,A12) -> 93 | C12: =COUNTIFS(Data!$D$2:$D$6232,A12,Data!$R$2:$R$6232,"RFE FILED") -> 83 | D12: =COUNTIFS(Data!$D$2:$D$6232,A12,Data!$R$2:$R$6232,"PROVISIONAL FILED") -> 10 | E12: =COUNTIFS(Data!$D$2:$D$6232,A12,Data!$R$2:$R$6232,"COMPLETE FILED") -> 0 | F12: =COUNTIFS(Data!$D$2:$D$6232,A12,Data!$R$2:$R$6232,"APPLICATION FILED") -> 0 | G12: =COUNTIFS(Data!$D$2:$D$6232,A12,Data!$R$2:$R$6232,"UNDER EXAMINATION") -> 0 | H12: =COUNTIFS(Data!$D$2:$D$6232,A12,Data!$R$2:$R$6232,"GRANTED") -> 0 | I12: =SUMPRODUCT((Data!$D$2:$D$6232=A12)*((Data!$R$2:$R$6232="ABANDONED")+(Data!$R$2:$R$6232="CLOSED")+(Data!$R$2:$R$6232="MERGED"))) -> 0 | J12: =COUNTIFS('Pending RQ Deadlines'!$C$2:$C$1271,A12,'Pending RQ Deadlines'!$K$2:$K$1271,"Yes") -> 10 | K12: =COUNTIFS('Pending RQ Deadlines'!$C$2:$C$1271,A12,'Pending RQ Deadlines'!$J$2:$J$1271,"OVERDUE") -> 2 | L12: =SUMPRODUCT(('Pending RQ Deadlines'!$C$2:$C$1271=A12)*('Pending RQ Deadlines'!$J$2:$J$1271<>"UPCOMING")*('Pending RQ Deadlines'!$K$2:$K$1271="Yes")) -> 3 | M12: =IFERROR(_xludf.minifs('Pending RQ Deadlines'!$G$2:$G$1271,'Pending RQ Deadlines'!$C$2:$C$1271,A12),"") | N12: =ROW()-L12+K12/100 -> 9.02
A13: RAKUTEN MOBILE INC | B13: =COUNTIF(Data!$D$2:$D$6232,A13) -> 92 | C13: =COUNTIFS(Data!$D$2:$D$6232,A13,Data!$R$2:$R$6232,"RFE FILED") -> 0 | D13: =COUNTIFS(Data!$D$2:$D$6232,A13,Data!$R$2:$R$6232,"PROVISIONAL FILED") -> 57 | E13: =COUNTIFS(Data!$D$2:$D$6232,A13,Data!$R$2:$R$6232,"COMPLETE FILED") -> 33 | F13: =COUNTIFS(Data!$D$2:$D$6232,A13,Data!$R$2:$R$6232,"APPLICATION FILED") -> 0 | G13: =COUNTIFS(Data!$D$2:$D$6232,A13,Data!$R$2:$R$6232,"UNDER EXAMINATION") -> 0 | H13: =COUNTIFS(Data!$D$2:$D$6232,A13,Data!$R$2:$R$6232,"GRANTED") -> 0 | I13: =SUMPRODUCT((Data!$D$2:$D$6232=A13)*((Data!$R$2:$R$6232="ABANDONED")+(Data!$R$2:$R$6232="CLOSED")+(Data!$R$2:$R$6232="MERGED"))) -> 2 | J13: =COUNTIFS('Pending RQ Deadlines'!$C$2:$C$1271,A13,'Pending RQ Deadlines'!$K$2:$K$1271,"Yes") -> 90 | K13: =COUNTIFS('Pending RQ Deadlines'!$C$2:$C$1271,A13,'Pending RQ Deadlines'!$J$2:$J$1271,"OVERDUE") -> 55 | L13: =SUMPRODUCT(('Pending RQ Deadlines'!$C$2:$C$1271=A13)*('Pending RQ Deadlines'!$J$2:$J$1271<>"UPCOMING")*('Pending RQ Deadlines'!$K$2:$K$1271="Yes")) -> 53 | M13: =IFERROR(_xludf.minifs('Pending RQ Deadlines'!$G$2:$G$1271,'Pending RQ Deadlines'!$C$2:$C$1271,A13),"") | N13: =ROW()-L13+K13/100 -> -39.45
... A607: ZUMUTOR BIOLOGICS, INC. | B607: =COUNTIF(Data!$D$2:$D$6232,A607) -> 1 | C607: =COUNTIFS(Data!$D$2:$D$6232,A607,Data!$R$2:$R$6232,"RFE FILED") -> 0 | D607: =COUNTIFS(Data!$D$2:$D$6232,A607,Data!$R$2:$R$6232,"PROVISIONAL FILED") -> 1 | E607: =COUNTIFS(Data!$D$2:$D$6232,A607,Data!$R$2:$R$6232,"COMPLETE FILED") -> 0 | F607: =COUNTIFS(Data!$D$2:$D$6232,A607,Data!$R$2:$R$6232,"APPLICATION FILED") -> 0 | G607: =COUNTIFS(Data!$D$2:$D$6232,A607,Data!$R$2:$R$6232,"UNDER EXAMINATION") -> 0 | H607: =COUNTIFS(Data!$D$2:$D$6232,A607,Data!$R$2:$R$6232,"GRANTED") -> 0 | I607: =SUMPRODUCT((Data!$D$2:$D$6232=A607)*((Data!$R$2:$R$6232="ABANDONED")+(Data!$R$2:$R$6232="CLOSED")+(Data!$R$2:$R$6232="MERGED"))) -> 0 | J607: =COUNTIFS('Pending RQ Deadlines'!$C$2:$C$1271,A607,'Pending RQ Deadlines'!$K$2:$K$1271,"Yes") -> 1 | K607: =COUNTIFS('Pending RQ Deadlines'!$C$2:$C$1271,A607,'Pending RQ Deadlines'!$J$2:$J$1271,"OVERDUE") -> 1 | L607: =SUMPRODUCT(('Pending RQ Deadlines'!$C$2:$C$1271=A607)*('Pending RQ Deadlines'!$J$2:$J$1271<>"UPCOMING")*('Pending RQ Deadlines'!$K$2:$K$1271="Yes")) -> 1 | M607: =IFERROR(_xludf.minifs('Pending RQ Deadlines'!$G$2:$G$1271,'Pending RQ Deadlines'!$C$2:$C$1271,A607),"") | N607: =ROW()-L607+K607/100 -> 606.01

Sheet Pending RQ Deadlines
A1: File No | B1: Application No | C1: Client Name | D1: Client Ref | E1: Status | F1: Filing Date | G1: RQ Due Date | H1: Days Remaining | I1: Months | J1: Urgency | K1: Action Required | L1: Column1 | M1: Column2
A2: IP91209 | B2: 202517111826 | C2: UNION TRANSLATIONS | D2: RECO091725 | E2: ABANDONED | F2: 45976 | G2: =EDATE(DataTable[[#This Row],[Priority Date]],31) -> 46784 | H2: =G2-TODAY() -> 527 | I2: =PendingRQTable[[#This Row],[Days Remaining]]/(365/12) -> 17.326027 | J2: =IF(H2<0,"OVERDUE",IF(H2<=30,"DUE <=30 DAYS",IF(H2<=90,"DUE <=90 DAYS","UPCOMING"))) -> UPCOMING | K2: =IF(E2="ABANDONED","No - Case Inactive","Yes") -> No - Case Inactive
A3: IP95031 | B3: 202617071212 | C3: SHENTALENT IP AGENCY CO LTD | D3: PLEASE PROVIDE | E3: APPLICATION FILED | F3: 46181 | G3: =EDATE(DataTable[[#This Row],[Priority Date]],31) -> 46784 | H3: =G3-TODAY() -> 527 | I3: =PendingRQTable[[#This Row],[Days Remaining]]/(365/12) -> 17.326027 | J3: =IF(H3<0,"OVERDUE",IF(H3<=30,"DUE <=30 DAYS",IF(H3<=90,"DUE <=90 DAYS","UPCOMING"))) -> UPCOMING | K3: =IF(E3="APPLICATION FILED","Yes","Yes") -> Yes
A4: IP93547 | B4: 202618014544 | C4: DINSMORE & SHOHL LLP | D4: PLEASE PROVIDE | E4: APPLICATION FILED | F4: 46063 | G4: =EDATE(DataTable[[#This Row],[Priority Date]],31) -> 46430 | H4: =G4-TODAY() -> 173 | I4: =PendingRQTable[[#This Row],[Days Remaining]]/(365/12) -> 5.6876712 | J4: =IF(H4<0,"OVERDUE",IF(H4<=30,"DUE <=30 DAYS",IF(H4<=90,"DUE <=90 DAYS","UPCOMING"))) -> UPCOMING | K4: =IF(E4="APPLICATION FILED","Yes","Yes") -> Yes
A5: IP89647 | B5: 202517096982 | C5: APPLEYARD LEES | D5: P45661INN1 | E5: APPLICATION FILED | F5: 45938 | G5: =EDATE(DataTable[[#This Row],[Priority Date]],31) -> 46221 | H5: =G5-TODAY() -> -36 | I5: =PendingRQTable[[#This Row],[Days Remaining]]/(365/12) -> -1.1835616 | J5: =IF(H5<0,"OVERDUE",IF(H5<=30,"DUE <=30 DAYS",IF(H5<=90,"DUE <=90 DAYS","UPCOMING"))) -> OVERDUE | K5: =IF(E5="APPLICATION FILED","Yes","Yes") -> Yes
A6: IP94313 | B6: 202648032709 | C6: SHEPPARD MULLIN RICHTER & HAMPTON LLP | D6: 67JG-335587-IN2 | E6: APPLICATION FILED | F6: 46099 | G6: =EDATE(DataTable[[#This Row],[Priority Date]],31) -> 45859 | H6: =G6-TODAY() -> -398 | I6: =PendingRQTable[[#This Row],[Days Remaining]]/(365/12) -> -13.084932 | J6: =IF(H6<0,"OVERDUE",IF(H6<=30,"DUE <=30 DAYS",IF(H6<=90,"DUE <=90 DAYS","UPCOMING"))) -> OVERDUE | K6: =IF(E6="APPLICATION FILED","Yes","Yes") -> Yes
A7: IP94365 | B7: 202618032821 | C7: BOEHMERT & BOEHMERT | D7: P11625WOIN-A | E7: APPLICATION FILED | F7: 46099 | G7: =EDATE(DataTable[[#This Row],[Priority Date]],31) -> 46419 | H7: =G7-TODAY() -> 162 | I7: =PendingRQTable[[#This Row],[Days Remaining]]/(365/12) -> 5.3260274 | J7: =IF(H7<0,"OVERDUE",IF(H7<=30,"DUE <=30 DAYS",IF(H7<=90,"DUE <=90 DAYS","UPCOMING"))) -> UPCOMING | K7: =IF(E7="APPLICATION FILED","Yes","Yes") -> Yes
A8: IP91023 | B8: 202547100848 | C8: APPLEYARD LEES | D8: P46226INN1 | E8: APPLICATION FILED | F8: 45947 | G8: =EDATE(DataTable[[#This Row],[Priority Date]],31) -> 46784 | H8: =G8-TODAY() -> 527 | I8: =PendingRQTable[[#This Row],[Days Remaining]]/(365/12) -> 17.326027 | J8: =IF(H8<0,"OVERDUE",IF(H8<=30,"DUE <=30 DAYS",IF(H8<=90,"DUE <=90 DAYS","UPCOMING"))) -> UPCOMING | K8: =IF(E8="APPLICATION FILED","Yes","Yes") -> Yes
A9: IP88699 | B9: 202517105776 | C9: KORYO IP & LAW | D9: LO-340348-PCTIN | E9: APPLICATION FILED | F9: 45962 | G9: =EDATE(DataTable[[#This Row],[Priority Date]],31) -> 46784 | H9: =G9-TODAY() -> 527 | I9: =PendingRQTable[[#This Row],[Days Remaining]]/(365/12) -> 17.326027 | J9: =IF(H9<0,"OVERDUE",IF(H9<=30,"DUE <=30 DAYS",IF(H9<=90,"DUE <=90 DAYS","UPCOMING"))) -> UPCOMING | K9: =IF(E9="APPLICATION FILED","Yes","Yes") -> Yes
A10: IP95417 | B10: 202618059571 | C10: ELI LILLY AND COMPANY | D10: X22015D_IN | E10: APPLICATION FILED | F10: 46153 | G10: =EDATE(DataTable[[#This Row],[Priority Date]],31) -> 45908 | H10: =G10-TODAY() -> -349 | I10: =PendingRQTable[[#This Row],[Days Remaining]]/(365/12) -> -11.473973 | J10: =IF(H10<0,"OVERDUE",IF(H10<=30,"DUE <=30 DAYS",IF(H10<=90,"DUE <=90 DAYS","UPCOMING"))) -> OVERDUE | K10: =IF(E10="APPLICATION FILED","Yes","Yes") -> Yes
A11: IP95787 | B11: 202648064836 | C11: SHENTALENT IP AGENCY CO LTD | D11: OP0021-IN-0621D1 | E11: APPLICATION FILED | F11: 46164 | G11: =EDATE(DataTable[[#This Row],[Priority Date]],31) -> 46784 | H11: =G11-TODAY() -> 527 | I11: =PendingRQTable[[#This Row],[Days Remaining]]/(365/12) -> 17.326027 | J11: =IF(H11<0,"OVERDUE",IF(H11<=30,"DUE <=30 DAYS",IF(H11<=90,"DUE <=90 DAYS","UPCOMING"))) -> UPCOMING | K11: =IF(E11="APPLICATION FILED","Yes","Yes") -> Yes
A12: IP89133 | B12: 202517099711 | C12: HAYNES AND BOONE LLP | D12: 60776.7IN01 | E12: APPLICATION FILED | F12: 45945 | G12: =EDATE(DataTable[[#This Row],[Priority Date]],31) -> 45910 | H12: =G12-TODAY() -> -347 | I12: =PendingRQTable[[#This Row],[Days Remaining]]/(365/12) -> -11.408219 | J12: =IF(H12<0,"OVERDUE",IF(H12<=30,"DUE <=30 DAYS",IF(H12<=90,"DUE <=90 DAYS","UPCOMING"))) -> OVERDUE | K12: =IF(E12="APPLICATION FILED","Yes","Yes") -> Yes
A13: IP92816 | B13: 202647014479 | C13: APPLEYARD LEES | D13: P46440INN1 | E13: APPLICATION FILED | F13: 46063 | G13: =EDATE(DataTable[[#This Row],[Priority Date]],31) -> 45840 | H13: =G13-TODAY() -> -417 | I13: =PendingRQTable[[#This Row],[Days Remaining]]/(365/12) -> -13.709589 | J13: =IF(H13<0,"OVERDUE",IF(H13<=30,"DUE <=30 DAYS",IF(H13<=90,"DUE <=90 DAYS","UPCOMING"))) -> OVERDUE | K13: =IF(E13="APPLICATION FILED","Yes","Yes") -> Yes
A14: IP85682 | B14: 202544062757 | C14: KASAN IP & LAW FIRM | D14: SMP230511IN | E14: APPLICATION FILED | F14: 45839 | G14: =EDATE(DataTable[[#This Row],[Priority Date]],31) -> 46784 | H14: =G14-TODAY() -> 527 | I14: =PendingRQTable[[#This Row],[Days Remaining]]/(365/12) -> 17.326027 | J14: =IF(H14<0,"OVERDUE",IF(H14<=30,"DUE <=30 DAYS",IF(H14<=90,"DUE <=90 DAYS","UPCOMING"))) -> UPCOMING | K14: =IF(E14="APPLICATION FILED","Yes","Yes") -> Yes
... A110: IP92362 | B110: 202644023642 | C110: KORYO IP & LAW | D110: LO-341819-IN | E110: APPLICATION FILED | F110: 46080 | G110: =EDATE(DataTable[[#This Row],[Priority Date]],31) -> 46790 | H110: =G110-TODAY() -> 533 | I110: =PendingRQTable[[#This Row],[Days Remaining]]/(365/12) -> 17.523288 | J110: =IF(H110<0,"OVERDUE",IF(H110<=30,"DUE <=30 DAYS",IF(H110<=90,"DUE <=90 DAYS","UPCOMING"))) -> UPCOMING | K110: =IF(E110="APPLICATION FILED","Yes","Yes") -> Yes
A111: IP93818 | B111: 202614021569 | C111: ANAQUA SERVICES INC | D111: P49851IN00 | E111: CLOSED | F111: 46077 | G111: =EDATE(DataTable[[#This Row],[Priority Date]],31) -> 46790 | H111: =G111-TODAY() -> 533 | I111: =PendingRQTable[[#This Row],[Days Remaining]]/(365/12) -> 17.523288 | J111: =IF(H111<0,"OVERDUE",IF(H111<=30,"DUE <=30 DAYS",IF(H111<=90,"DUE <=90 DAYS","UPCOMING"))) -> UPCOMING | K111: =IF(E111="CLOSED","No - Case Inactive","Yes") -> No - Case Inactive
A112: IP91334 | B112: 202614021223 | C112: KORYO IP & LAW | D112: LO-341601-IN | E112: APPLICATION FILED | F112: 46076 | G112: =EDATE(DataTable[[#This Row],[Priority Date]],31) -> 45915 | H112: =G112-TODAY() -> -342 | I112: =PendingRQTable[[#This Row],[Days Remaining]]/(365/12) -> -11.243836 | J112: =IF(H112<0,"OVERDUE",IF(H112<=30,"DUE <=30 DAYS",IF(H112<=90,"DUE <=90 DAYS","UPCOMING"))) -> OVERDUE | K112: =IF(E112="APPLICATION FILED","Yes","Yes") -> Yes
A113: IP91099 | B113: 202644025590 | C113: KASAN IP & LAW FIRM | D113: SMP240612IN | E113: APPLICATION FILED | F113: 46085 | G113: =EDATE(DataTable[[#This Row],[Priority Date]],31) -> 46790 | H113: =G113-TODAY() -> 533 | I113: =PendingRQTable[[#This Row],[Days Remaining]]/(365/12) -> 17.523288 | J113: =IF(H113<0,"OVERDUE",IF(H113<=30,"DUE <=30 DAYS",IF(H113<=90,"DUE <=90 DAYS","UPCOMING"))) -> UPCOMING | K113: =IF(E113="APPLICATION FILED","Yes","Yes") -> Yes
A114: IP93422 | B114: 202644013103 | C114: FOLEY & LARDNER LLP | D114: 106389-9730 | E114: APPLICATION FILED | F114: 46059 | G114: =EDATE(DataTable[[#This Row],[Priority Date]],31) -> 45866 | H114: =G114-TODAY() -> -391 | I114: =PendingRQTable[[#This Row],[Days Remaining]]/(365/12) -> -12.854795 | J114: =IF(H114<0,"OVERDUE",IF(H114<=30,"DUE <=30 DAYS",IF(H114<=90,"DUE <=90 DAYS","UPCOMING"))) -> OVERDUE | K114: =IF(E114="APPLICATION FILED","Yes","Yes") -> Yes
A115: IP91436 | B115: 202614011184 | C115: KASAN IP & LAW FIRM | D115: SMP240453IN | E115: APPLICATION FILED | F115: 46056 | G115: =EDATE(DataTable[[#This Row],[Priority Date]],31) -> 46137 | H115: =G115-TODAY() -> -120 | I115: =PendingRQTable[[#This Row],[Days Remaining]]/(365/12) -> -3.9452055 | J115: =IF(H115<0,"OVERDUE",IF(H115<=30,"DUE <=30 DAYS",IF(H115<=90,"DUE <=90 DAYS","UPCOMING"))) -> OVERDUE | K115: =IF(E115="APPLICATION FILED","Yes","Yes") -> Yes
A116: IP91594 | B116: 202644028715 | C116: 21ST CENTURY PATENT & LAW FIRM | D116: HZ3187IN/SB | E116: APPLICATION FILED | F116: 46092 | G116: =EDATE(DataTable[[#This Row],[Priority Date]],31) -> 46790 | H116: =G116-TODAY() -> 533 | I116: =PendingRQTable[[#This Row],[Days Remaining]]/(365/12) -> 17.523288 | J116: =IF(H116<0,"OVERDUE",IF(H116<=30,"DUE <=30 DAYS",IF(H116<=90,"DUE <=90 DAYS","UPCOMING"))) -> UPCOMING | K116: =IF(E116="APPLICATION FILED","Yes","Yes") -> Yes
A117: IP91519 | B117: 202614016094 | C117: KORYO IP & LAW | D117: LO-341014-IN | E117: APPLICATION FILED | F117: 46066 | G117: =EDATE(DataTable[[#This Row],[Priority Date]],31) -> 46790 | H117: =G117-TODAY() -> 533 | I117: =PendingRQTable[[#This Row],[Days Remaining]]/(365/12) -> 17.523288 | J117: =IF(H117<0,"OVERDUE",IF(H117<=30,"DUE <=30 DAYS",IF(H117<=90,"DUE <=90 DAYS","UPCOMING"))) -> UPCOMING | K117: =IF(E117="APPLICATION FILED","Yes","Yes") -> Yes
A118: IP93603 | B118: 202644029356 | C118: GENERAL ELECTRIC | D118: 701474-IN-4 | E118: APPLICATION FILED | F118: 46093 | G118: =EDATE(DataTable[[#This Row],[Priority Date]],31) -> 45848 | H118: =G118-TODAY() -> -409 | I118: =PendingRQTable[[#This Row],[Days Remaining]]/(365/12) -> -13.446575 | J118: =IF(H118<0,"OVERDUE",IF(H118<=30,"DUE <=30 DAYS",IF(H118<=90,"DUE <=90 DAYS","UPCOMING"))) -> OVERDUE | K118: =IF(E118="APPLICATION FILED","Yes","Yes") -> Yes
A119: IP94239 | B119: 202644029409 | C119: K AND L GATES LLP | D119: 7601410.00216-IN | E119: APPLICATION FILED | F119: 46093 | G119: =EDATE(DataTable[[#This Row],[Priority Date]],31) -> 45846 | H119: =G119-TODAY() -> -411 | I119: =PendingRQTable[[#This Row],[Days Remaining]]/(365/12) -> -13.512329 | J119: =IF(H119<0,"OVERDUE",IF(H119<=30,"DUE <=30 DAYS",IF(H119<=90,"DUE <=90 DAYS","UPCOMING"))) -> OVERDUE | K119: =IF(E119="APPLICATION FILED","Yes","Yes") -> Yes
A120: IP93878 | B120: 202614025077 | C120: Fortmann Tegethoff GbR | D120: 31082.20683IN | E120: APPLICATION FILED | F120: 46084 | G120: =EDATE(DataTable[[#This Row],[Priority Date]],31) -> 45858 | H120: =G120-TODAY() -> -399 | I120: =PendingRQTable[[#This Row],[Days Remaining]]/(365/12) -> -13.117808 | J120: =IF(H120<0,"OVERDUE",IF(H120<=30,"DUE <=30 DAYS",IF(H120<=90,"DUE <=90 DAYS","UPCOMING"))) -> OVERDUE | K120: =IF(E120="APPLICATION FILED","Yes","Yes") -> Yes
A121: IP93652 | B121: 202644024995 | C121: GRUNECKER | D121: PA152261IN-GM405903KAF | E121: APPLICATION FILED | F121: 46084 | G121: =EDATE(DataTable[[#This Row],[Priority Date]],31) -> 45857 | H121: =G121-TODAY() -> -400 | I121: =PendingRQTable[[#This Row],[Days Remaining]]/(365/12) -> -13.150685 | J121: =IF(H121<0,"OVERDUE",IF(H121<=30,"DUE <=30 DAYS",IF(H121<=90,"DUE <=90 DAYS","UPCOMING"))) -> OVERDUE | K121: =IF(E121="APPLICATION FILED","Yes","Yes") -> Yes
A122: IP94228 | B122: 202614032773 | C122: Y.P. LEE, MOCK & PARTNERS | D122: SS-81078-IN | E122: APPLICATION FILED | F122: 46099 | G122: =EDATE(DataTable[[#This Row],[Priority Date]],31) -> 46790 | H122: =G122-TODAY() -> 533 | I122: =PendingRQTable[[#This Row],[Days Remaining]]/(365/12) -> 17.523288 | J122: =IF(H122<0,"OVERDUE",IF(H122<=30,"DUE <=30 DAYS",IF(H122<=90,"DUE <=90 DAYS","UPCOMING"))) -> UPCOMING | K122: =IF(E122="APPLICATION FILED","Yes","Yes") -> Yes
A123: IP93664 | B123: 202614033675 | C123: KORYO IP & LAW | D123: LO-350048-IN | E123: APPLICATION FILED | F123: 46101 | G123: =EDATE(DataTable[[#This Row],[Priority Date]],31) -> 45845 | H123: =G123-TODAY() -> -412 | I123: =PendingRQTable[[#This Row],[Days Remaining]]/(365/12) -> -13.545205 | J123: =IF(H123<0,"OVERDUE",IF(H123<=30,"DUE <=30 DAYS",IF(H123<=90,"DUE <=90 DAYS","UPCOMING"))) -> OVERDUE | K123: =IF(E123="APPLICATION FILED","Yes","Yes") -> Yes
... A163: IP96166 | B163: 202614073180 | C163: KOKUSAI ELECTRIC CORPORATION | D163: 1000582IN01 | E163: APPLICATION FILED | F163: 46185 | G163: =EDATE(DataTable[[#This Row],[Priority Date]],31) -> 46097 | H163: =G163-TODAY() -> -160 | I163: =PendingRQTable[[#This Row],[Days Remaining]]/(365/12) -> -5.260274 | J163: =IF(H163<0,"OVERDUE",IF(H163<=30,"DUE <=30 DAYS",IF(H163<=90,"DUE <=90 DAYS","UPCOMING"))) -> OVERDUE | K163: =IF(E163="APPLICATION FILED","Yes","Yes") -> Yes
A164: IP88072 | B164: 202541062777 | C164: HEXITRONICS AUTOMATION LLP | D164: PLEASE PROVIDE | E164: PROVISIONAL FILED | F164: 45839 | G164: =EDATE(DataTable[[#This Row],[Priority Date]],31) -> 45858 | H164: =G164-TODAY() -> -399 | I164: =PendingRQTable[[#This Row],[Days Remaining]]/(365/12) -> -13.117808 | J164: =IF(H164<0,"OVERDUE",IF(H164<=30,"DUE <=30 DAYS",IF(H164<=90,"DUE <=90 DAYS","UPCOMING"))) -> OVERDUE | K164: =IF(E164="PROVISIONAL FILED","Yes","Yes") -> Yes
A165: IP87164 | B165: 202511063152 | C165: ICAR-CENTRAL SHEEP & WOOL RESEARCH INSTITUTE | D165: PLEASE PROVIDE | E165: PROVISIONAL FILED | F165: 45840 | G165: =EDATE(DataTable[[#This Row],[Priority Date]],31) -> 45868 | H165: =G165-TODAY() -> -389 | I165: =PendingRQTable[[#This Row],[Days Remaining]]/(365/12) -> -12.789041 | J165: =IF(H165<0,"OVERDUE",IF(H165<=30,"DUE <=30 DAYS",IF(H165<=90,"DUE <=90 DAYS","UPCOMING"))) -> OVERDUE | K165: =IF(E165="PROVISIONAL FILED","Yes","Yes") -> Yes
A166: IP88460 | B166: 202541064158 | C166: HAMILTON BROOK SMITH REYNOLDS | D166: 4316.1031-001 IN | E166: ABANDONED | F166: 45842 | G166: =EDATE(DataTable[[#This Row],[Priority Date]],31) -> 45879 | H166: =G166-TODAY() -> -378 | I166: =PendingRQTable[[#This Row],[Days Remaining]]/(365/12) -> -12.427397 | J166: =IF(H166<0,"OVERDUE",IF(H166<=30,"DUE <=30 DAYS",IF(H166<=90,"DUE <=90 DAYS","UPCOMING"))) -> OVERDUE | K166: =IF(E166="ABANDONED","No - Case Inactive","Yes") -> No - Case Inactive
A167: IP86963 | B167: 202541064215 | C167: MERCEDES-BENZ INTELLECTUAL PROPERTY GMBH & CO KG | D167: 2025P00793 IN | E167: COMPLETE FILED | F167: 45842 | G167: =EDATE(DataTable[[#This Row],[Priority Date]],31) -> 46793 | H167: =G167-TODAY() -> 536 | I167: =PendingRQTable[[#This Row],[Days Remaining]]/(365/12) -> 17.621918 | J167: =IF(H167<0,"OVERDUE",IF(H167<=30,"DUE <=30 DAYS",IF(H167<=90,"DUE <=90 DAYS","UPCOMING"))) -> UPCOMING | K167: =IF(E167="COMPLETE FILED","Yes","Yes") -> Yes
A168: IP85648 | B168: 202541063903 | C168: AMRITA CENTRE FOR NANOSCIENCES & | D168: ASP-001500INP | E168: PROVISIONAL FILED | F168: 45842 | G168: =EDATE(DataTable[[#This Row],[Priority Date]],31) -> 46793 | H168: =G168-TODAY() -> 536 | I168: =PendingRQTable[[#This Row],[Days Remaining]]/(365/12) -> 17.621918 | J168: =IF(H168<0,"OVERDUE",IF(H168<=30,"DUE <=30 DAYS",IF(H168<=90,"DUE <=90 DAYS","UPCOMING"))) -> UPCOMING | K168: =IF(E168="PROVISIONAL FILED","Yes","Yes") -> Yes
A169: IP87053 | B169: 202541064082 | C169: STRING BIO PRIVATE LIMITED | D169: PLEASE PROVIDE | E169: PROVISIONAL FILED | F169: 45842 | G169: =EDATE(DataTable[[#This Row],[Priority Date]],31) -> 46793 | H169: =G169-TODAY() -> 536 | I169: =PendingRQTable[[#This Row],[Days Remaining]]/(365/12) -> 17.621918 | J169: =IF(H169<0,"OVERDUE",IF(H169<=30,"DUE <=30 DAYS",IF(H169<=90,"DUE <=90 DAYS","UPCOMING"))) -> UPCOMING | K169: =IF(E169="PROVISIONAL FILED","Yes","Yes") -> Yes
A170: IP88375 | B170: 202541064056 | C170: HAYNES AND BOONE LLP | D170: 59103.145PV01 | E170: ABANDONED | F170: 45842 | G170: =EDATE(DataTable[[#This Row],[Priority Date]],31) -> 46793 | H170: =G170-TODAY() -> 536 | I170: =PendingRQTable[[#This Row],[Days Remaining]]/(365/12) -> 17.621918 | J170: =IF(H170<0,"OVERDUE",IF(H170<=30,"DUE <=30 DAYS",IF(H170<=90,"DUE <=90 DAYS","UPCOMING"))) -> UPCOMING | K170: =IF(E170="ABANDONED","No - Case Inactive","Yes") -> No - Case Inactive
A171: IP88439 | B171: 202541063856 | C171: RAKUTEN MOBILE INC | D171: PI25-00358IN01 | E171: PROVISIONAL FILED | F171: 45842 | G171: =EDATE(DataTable[[#This Row],[Priority Date]],31) -> 46428 | H171: =G171-TODAY() -> 171 | I171: =PendingRQTable[[#This Row],[Days Remaining]]/(365/12) -> 5.6219178 | J171: =IF(H171<0,"OVERDUE",IF(H171<=30,"DUE <=30 DAYS",IF(H171<=90,"DUE <=90 DAYS","UPCOMING"))) -> UPCOMING | K171: =IF(E171="PROVISIONAL FILED","Yes","Yes") -> Yes
A172: IP85500 | B172: 202541042715 | C172: MC KUMARI | D172: MS-CPDM-2025-020 | E172: PROVISIONAL FILED | F172: 45843 | G172: =EDATE(DataTable[[#This Row],[Priority Date]],31) -> 45853 | H172: =G172-TODAY() -> -404 | I172: =PendingRQTable[[#This Row],[Days Remaining]]/(365/12) -> -13.282192 | J172: =IF(H172<0,"OVERDUE",IF(H172<=30,"DUE <=30 DAYS",IF(H172<=90,"DUE <=90 DAYS","UPCOMING"))) -> OVERDUE | K172: =IF(E172="PROVISIONAL FILED","Yes","Yes") -> Yes
A173: IP85501 | B173: 202541043951 | C173: MC KUMARI | D173: MS-CPDM-2025-021 | E173: PROVISIONAL FILED | F173: 45844 | G173: =EDATE(DataTable[[#This Row],[Priority Date]],31) -> 46793 | H173: =G173-TODAY() -> 536 | I173: =PendingRQTable[[#This Row],[Days Remaining]]/(365/12) -> 17.621918 | J173: =IF(H173<0,"OVERDUE",IF(H173<=30,"DUE <=30 DAYS",IF(H173<=90,"DUE <=90 DAYS","UPCOMING"))) -> UPCOMING | K173: =IF(E173="PROVISIONAL FILED","Yes","Yes") -> Yes
A174: IP89570 | B174: 202511064704 | C174: DEFENCE RESEARCH & DEVELOPMENT ORG (DRDO) | D174: ERIP/IP/2401039/M/01 | E174: RFE FILED | F174: 45845 | G174: =EDATE(DataTable[[#This Row],[Priority Date]],31) -> 46793 | H174: =G174-TODAY() -> 536 | I174: =PendingRQTable[[#This Row],[Days Remaining]]/(365/12) -> 17.621918 | J174: =IF(H174<0,"OVERDUE",IF(H174<=30,"DUE <=30 DAYS",IF(H174<=90,"DUE <=90 DAYS","UPCOMING"))) -> UPCOMING | K174: =IF(E174="RFE FILED","Yes","Yes") -> Yes
...

Sheet Status Overview
A1: Status | B1: Case Count | C1: % of Total
A2: RFE FILED | B2: =COUNTIF(Data!$R$2:$R$6232,A2) -> 4607 | C2: =B2/6052 -> 0.76123596
A3: PROVISIONAL FILED | B3: =COUNTIF(Data!$R$2:$R$6232,A3) -> 805 | C3: =B3/6052 -> 0.13301388
A4: COMPLETE FILED | B4: =COUNTIF(Data!$R$2:$R$6232,A4) -> 245 | C4: =B4/6052 -> 0.040482485
A5: APPLICATION FILED | B5: =COUNTIF(Data!$R$2:$R$6232,A5) -> 171 | C5: =B5/6052 -> 0.028255122
A6: UNDER EXAMINATION | B6: =COUNTIF(Data!$R$2:$R$6232,A6) -> 74 | C6: =B6/6052 -> 0.012227363
A7: ABANDONED | B7: =COUNTIF(Data!$R$2:$R$6232,A7) -> 63 | C7: =B7/6052 -> 0.010409782
A8: RE-FILED | B8: =COUNTIF(Data!$R$2:$R$6232,A8) -> 23 | C8: =B8/6052 -> 0.0038003966
A9: CLOSED | B9: =COUNTIF(Data!$R$2:$R$6232,A9) -> 17 | C9: =B9/6052 -> 0.0028089888
A10: GRANTED | B10: =COUNTIF(Data!$R$2:$R$6232,A10) -> 13 | C10: =B10/6052 -> 0.0021480502
A11: DO NOT INCUR | B11: =COUNTIF(Data!$R$2:$R$6232,A11) -> 9 | C11: =B11/6052 -> 0.0014871117
A12: WITHDRAWAL FILED(REFUND) | B12: =COUNTIF(Data!$R$2:$R$6232,A12) -> 8 | C12: =B12/6052 -> 0.0013218771
A13: HEARING | B13: =COUNTIF(Data!$R$2:$R$6232,A13) -> 6 | C13: =B13/6052 -> 0.0009914078
... A18: DRAFTING | B18: =COUNTIF(Data!$R$2:$R$6232,A18) -> 1 | C18: =B18/6052 -> 0.00016523463
A20: TOTAL | B20: =SUM(B2:B18) -> 6052

Sheet Data
A1: Sr. No. | B1: File No | C1: Application No | D1: Client Name | E1: Client Ref | F1: Client Country | G1: Applicant | H1: Title | I1: Provisional/Complete | J1: Branch | K1: Case Recv. On | L1: Priority Date | M1: Filing Date | N1: RQ Due | O1: RQ Filed | P1: Attorney | Q1: Paralegal | R1: Status
A2: 1 | B2: IP88038 | C2: 202517062668 | D2: CROSS-BORDER PATENT FIRM | E2: 684500IN01OMNA | F2: Japan | G2: MITSUBISHI ELECTRIC CORPORATION | H2: STATE TRANSITION MANAGEMENT APPARATUS AND STATE TRANSITION MANAGEMENT METHOD PCT/JP2023/005999 | J2: GURGAON | K2: 45821 | L2: 45839 | M2: 45839 | O2: 45839 | P2: Sumukh A | Q2: Ravi Mishra | R2: RFE FILED
A3: 2 | B3: IP85070 | C3: 202511062810 | D3: The Director ICAR NIVEDI | E3: PLEASE PROVIDE | F3: India | G3: INDIAN COUNCIL OF AGRICULTURAL RESEARCH (ICAR) | H3: RECOMBINANT MUTANT EPSILON (rETX) FUSION PROTEIN AND THE METHOD OF PREPARATION THEREOF | I3: Complete Filed | J3: GURGAON | K3: 45678 | L3: 45839 | M3: 45839 | O3: 45846 | P3: Samriti Sanjgotra | Q3: Nitika Anand | R3: RFE FILED
A4: 3 | B4: IP88153 | C4: 202544062608 | D4: GRUNECKER | E4: PA148458IN-TG433903JFE | F4: Germany | G4: KRONES AG | H4: CONTAINER TREATMENT MACHINE FOR TREATING CONTAINERS | J4: GURGAON | K4: 45827 | L4: 45485 | M4: 45839 | O4: 45839 | P4: Sandesh Sastry | Q4: Gurleen Kaur | R4: RFE FILED
A5: 4 | B5: IP87829 | C5: 202517062664 | D5: YOU ME PATENT & LAW FIRM | E5: OPP20243406IN | F5: Korea | G5: LG ENERGY SOLUTION, LTD. | H5: APPARATUS AND METHOD OF ESTIMATING THE BATTERY INTERNAL RESISTANCE PCT/KR2024/008470 | J5: GURGAON | K5: 45812 | L5: 45278 | M5: 45839 | O5: 45839 | P5: Sonali Mewar | Q5: Arun Kumar | R5: RFE FILED
A6: 5 | B6: IP86294 | C6: 202517062728 | D6: YOU ME PATENT & LAW FIRM | E6: OPP20250928IN | F6: Korea | G6: POSCO CO., LTD | H6: ADHESIVE COATING COMPOSITION FOR ELECTRICAL STEEL SHEET, ELECTRICAL STEEL SHEET LAMINATE, AND METHOD FOR MANUFACTURING SAME PCT/KR2023/017729 | J6: GURGAON | K6: 45729 | L6: 44916 | M6: 45839 | O6: 45839 | P6: Yameeni Sarothia | Q6: Arub Mistree | R6: RFE FILED
A7: 6 | B7: IP85682 | C7: 202544062757 | D7: KASAN IP & LAW FIRM | E7: SMP230511IN | F7: Korea | G7: SAMSUNG DISPLAY CO., LTD. | H7: DISPLAY DEVICE AND OPTICAL DEVICE INCLUDING THE SAME | J7: GURGAON | K7: 45708 | L7: 45474 | M7: 45839 | N7: 46419 | P7: Mohamed Ghouse | Q7: Ravi Prakashan PK | R7: APPLICATION FILED
A8: 7 | B8: IP86368 | C8: 202541062582 | D8: INDIAN INSTITUTE OF SCIENCE | E8: CS-OC-2025-043 | F8: India | G8: INDIAN INSTITUTE OF SCIENCE | H8: IONIZABLE LIPID PROCESS OF PREPARING SAME AND APPLICATIONS THEREOF | I8: Complete Filed | J8: GURGAON | K8: 45733 | L8: 45839 | M8: 45839 | O8: 45839 | P8: Indrani Adhikari | Q8: Sunil Gaur | R8: RFE FILED
A9: 8 | B9: IP86936 | C9: 202541062563 | D9: INDIAN INSTITUTE OF SCIENCE | E9: CS-OC-2025-064 | F9: India | G9: INDIAN INSTITUTE OF SCIENCE | H9: PROCESS FOR PREPARATION OF IONIZABLE LIPIDS | I9: Complete Filed | J9: GURGAON | K9: 45763 | L9: 45839 | M9: 45839 | O9: 45839 | P9: Indrani Adhikari | Q9: Sunil Gaur | R9: GRANTED
A10: 9 | B10: IP88253 | C10: 202547062617 | D10: QUALCOMM INCORPORATED | E10: 2207346IN | F10: United States Of America | G10: QUALCOMM INCORPORATED | H10: USER EQUIPMENT (UE) FULL-DUPLEX OPERATION PCT/US2024/012185 | J10: GURGAON | K10: 45833 | L10: 44965 | M10: 45839 | O10: 45839 | P10: Abhimanyu Singh | Q10: Anand Yenurkar | R10: RFE FILED
A11: 10 | B11: IP88255 | C11: 202547062788 | D11: QUALCOMM INCORPORATED | E11: 2208615IN | F11: United States Of America | G11: QUALCOMM INCORPORATED | H11: POSITION SENSING BASED ON RECONFIGURABLE INTELLIGENT SURFACE (RIS) REFLECTION SCHEDULE PCT/CN2023/074750 | J11: GURGAON | K11: 45833 | L11: 45839 | M11: 45839 | O11: 45839 | P11: Harshitha R | Q11: Chaitra K G | R11: RFE FILED
A12: 11 | B12: IP88281 | C12: 202547062774 | D12: QUALCOMM INCORPORATED | E12: 2301877IN | F12: United States Of America | G12: QUALCOMM INCORPORATED | H12: RESOURCE BLOCK GROUP SIZES PCT/US2024/014507 | J12: GURGAON | K12: 45833 | L12: 44967 | M12: 45839 | O12: 45839 | P12: Kshama Gaitonde | Q12: Mani V S | R12: RFE FILED
A13: 12 | B13: IP87727 | C13: 202517062809 | D13: LATHROP GPM LLP | E13: 766130: KNT-001IN | F13: United States Of America | G13: KINASET THERAPEUTICS, INC. | H13: FORMULATION OF A PAN-JAK INHIBITOR PCT/US2023/082047 | J13: GURGAON | K13: 45807 | L13: 44897 | M13: 45839 | O13: 45839 | P13: Anamika Thakur | Q13: Ranjana Verma | R13: RFE FILED
A14: 13 | B14: IP87956 | C14: 202517062769 | D14: SAKAI INTERNATIONAL PATENT OFFICE | E14: PMAA-250092-IN | F14: Japan | G14: MITSUBISHI ELECTRIC CORPORATION | H14: SYNCHRONOUS RELUCTANCE MOTOR ABNORMALITY DETECTION DEVICE AND ABNORMALITY DETECTION METHOD PCT/JP2023/001968 | J14: GURGAON | K14: 45818 | L14: 45839 | M14: 45839 | O14: 45839 | P14: Sanjit Kumar | Q14: Anand Yenurkar | R14: RFE FILED
A15: 14 | B15: IP86672 | C15: 202547062727 | D15: JUNHE LAW OFFICES | E15: 087718-8004IN01 | F15: China | G15: SHANGHAI ARGO BIOPHARMACEUTICAL CO., LTD | H15: BICYCLIC ABASIC NUCLEIC ACID ANALOGS AND OLIGOMERIC COMPOUNDS PREPARED THEREFROM PCT/CN2023/135759 | J15: GURGAON | K15: 45747 | L15: 44897 | M15: 45839 | O15: 45839 | P15: Sneha Menon | Q15: Renuka R | R15: RFE FILED
A16: 15 | B16: IP87069 | C16: 202517062627 | D16: KADOR & PARTNER | E16: K 76 272/13DO | F16: Germany | G16: BOREALIS AG | H16: PROCESS FOR PRODUCING A POLYPROPYLENE COPOLYMER PCT/EP2023/086302 | J16: GURGAON | K16: 45770 | L16: 44918 | M16: 45839 | O16: 45845 | P16: Indrani Adhikari | Q16: Sunil Gaur | R16: RFE FILED
A17: 16 | B17: IP87641 | C17: 202517062618 | D17: K&L GATES LLP | E17: 1959952.00050 | F17: United States Of America | G17: ASPERA BIOMEDICINES, INC. | H17: CHEMOENZYMATIC SYNTHESIS OF POLYKETIDES PCT/US2023/082140 | J17: GURGAON | K17: 45803 | L17: 44896 | M17: 45839 | O17: 45839 | P17: Juhi Rajiv Sakrikar | Q17: Gaurav Gupta | R17: RFE FILED
A18: 17 | B18: IP87835 | C18: 202517062731 | D18: PHIL & ONZI | E18: OVP2425164IN | F18: Korea | G18: LG ENERGY SOLUTION, LTD. | H18: WELDING HEAT-SHIELDING MEMBER, ELECTRODE ASSEMBLY DAMAGE PREVENTION STRUCTURE USING SAME, AND BATTERY CELL USING SAME PCT/KR2024/007517 | J18: GURGAON | K18: 45812 | L18: 45104 | M18: 45839 | O18: 45839 | P18: Ankur Saxena | Q18: Shalu Saxena | R18: RFE FILED
A19: 18 | B19: IP88346 | C19: 202517062706 | D19: IBM CORPORATION | E19: P202202274IN01 | F19: United States Of America | G19: INTERNATIONAL BUSINESS MACHINES CORPORATION | H19: PROXIMITY HEATER TO LOWER RRAM FORMING VOLTAGE PCT/EP2023/083112 | J19: GURGAON | K19: 45835 | L19: 44897 | M19: 45839 | O19: 45839 | P19: Riti Sethi | Q19: Manas Maity | R19: RFE FILED
A20: 19 | B20: IP88349 | C20: 202517062987 | D20: IBM CORPORATION | E20: P202201514IN01 | F20: United States Of America | G20: INTERNATIONAL BUSINESS MACHINES CORPORATION | H20: PHASE-CHANGE MEMORY CELL WITH MIXED-MATERIAL SWITCHABLE REGION PCT/CN2023/132548 | J20: GURGAON | K20: 45835 | L20: 44903 | M20: 45839 | O20: 45839 | P20: Sanjit Kumar | Q20: Anand Yenurkar | R20: RFE FILED
A21: 20 | B21: IP88209 | C21: 202547062688 | D21: IPG PHOTONICS CORPORATION | E21: P22381/IN | F21: United States Of America | G21: IPG PHOTONICS CORPORATION | H21: PROTECTIVE MULTIWINDOW CARTRIDGE ASSEMBLY PCT/US2023/083326 | J21: GURGAON | K21: 45831 | L21: 44921 | M21: 45839 | O21: 45839 | P21: Nikhil K R | Q21: M Vijaya Lakshmi | R21: RFE FILED
A22: 21 | B22: IP88072 | C22: 202541062777 | D22: HEXITRONICS AUTOMATION LLP | E22: PLEASE PROVIDE | F22: India | G22: HEXITRONICS AUTOMATION LLP | H22: METHOD AND SYSTEM FOR AUTO-CONFIGURABLE IOT DEVICES WITH DYNAMIC DASHBOARD GENERATION | I22: Provisional | J22: GURGAON | K22: 45825 | L22: 45839 | M22: 45839 | N22: 46784 | P22: Kshama Gaitonde | Q22: Mani V S | R22: PROVISIONAL FILED
A23: 22 | B23: IP88114 | C23: 202517062625 | D23: PEARCE IP | E23: 25900INP00 | F23: New Zealand | G23: WEIR SCIENCE LIMITED | H23: POLLEN-BASED COMPOSITIONS AND EXTRACTS FOR STIMULATING HYALURONIC ACID PRODUCTION PCT/NZ2023/050143 | J23: GURGAON | K23: 45826 | L23: 44897 | M23: 45839 | O23: 45839 | P23: Sachin Bindal | Q23: Chetna Veer | R23: RFE FILED
A24: 23 | B24: IP85280 | C24: 202511063083 | D24: The Director ICAR NIVEDI | E24: PLEASE PROVIDE | F24: India | G24: INDIAN COUNCIL OF AGRICULTURAL RESEARCH (ICAR) | H24: RECOMBINANT A27L PROTEIN, A KIT AND AN ASSAY FOR IDENTIFYING LUMPY SKIN DISEASE VIRUS (LSDV) | I24: Complete Filed | J24: BANGALORE | K24: 45687 | L24: 45840 | M24: 45840 | O24: 45917 | P24: Samriti Sanjgotra | Q24: Nitika Anand | R24: UNDER EXAMINATION
A25: 24 | B25: IP87102 | C25: 202541063209 | D25: ABB SWITZERLAND LTD. | E25: P241066IN01 | F25: Switzerland | G25: ABB SCHWEIZ AG | H25: METHOD AND APPARATUS FOR RECOMMENDING COLLABORATIVE LEARNING TECHNIQUE | I25: Complete Filed | J25: GURGAON | K25: 45771 | L25: 45840 | M25: 45840 | O25: 45840 | P25: Manju Thomas | Q25: Ravi Mishra | R25: RFE FILED
A26: 25 | B26: IP87822 | C26: 202517063207 | D26: Visa Inc. | E26: 6849IN02 | F26: United States Of America | G26: VISA INTERNATIONAL SERVICE ASSOCIATION | H26: SYSTEM AND METHOD FOR A NETWORK AUTHENTICATION WITH DEVICE LEVEL AUTHENTICATION CONTROLS PCT/US2023/083491 | J26: GURGAON | K26: 45812 | L26: 44908 | M26: 45840 | O26: 45840 | P26: Neilotpal Mukhopadhyay | Q26: Kamlesh Negi | R26: RFE FILED
A27: 26 | B27: IP87698 | C27: 202517063108 | D27: V.O. PATENTS & TRADEMARKS | E27: P133519IN00 | F27: Netherlands | G27: RIJKSUNIVERSITEIT GRONINGEN | H27: NANOBODY-FUNCTIONALIZED BIOLOGICAL NANOPORES AND MEANS AND METHODS RELATED THERETO PCT/NL2023/050633 | J27: GURGAON | K27: 45806 | L27: 44897 | M27: 45840 | O27: 45840 | P27: Samriti Sanjgotra | Q27: Nitika Anand | R27: RFE FILED
A28: 27 | B28: IP88305 | C28: 202547063115 | D28: QUALCOMM INCORPORATED | E28: 2301341IN | F28: United States Of America | G28: QUALCOMM INCORPORATED | H28: SIGNALING DESIGN FOR TD BEAM PREDICTION WITH FLEXIBLE MEASUREMENT AND PREDICTION CYCLES PCT/CN2023/076717 | J28: GURGAON | K28: 45834 | L28: 45840 | M28: 45840 | O28: 45840 | P28: Kshama Gaitonde | Q28: Mani V S | R28: RFE FILED
A29: 28 | B29: IP88309 | C29: 202547063268 | D29: QUALCOMM INCORPORATED | E29: 2301225IN | F29: United States Of America | G29: QUALCOMM INCORPORATED | H29: DELTA CONFIGURATION FOR LAYER 1/LAYER 2 TRIGGERED MOBILITY PCT/US2024/011979 | J29: GURGAON | K29: 45834 | L29: 44972 | M29: 45840 | O29: 45840 | P29: Kshama Gaitonde | Q29: Mani V S | R29: RFE FILED
A30: 29 | B30: IP88312 | C30: 202547063013 | D30: QUALCOMM INCORPORATED | E30: 2302648IN | F30: United States Of America | G30: QUALCOMM INCORPORATED | H30: MODEL SELECTION AND DELIVERY PCT/US2024/011694 | J30: GURGAON | K30: 45834 | L30: 44971 | M30: 45840 | O30: 45840 | P30: Harshitha R | Q30: Chaitra K G | R30: RFE FILED
A31: 30 | B31: IP88314 | C31: 202547063119 | D31: QUALCOMM INCORPORATED | E31: 2302794IN | F31: United States Of America | G31: QUALCOMM INCORPORATED | H31: RELAY ASSISTED FULL DUPLEX RELAY FROM NETWORK TO REMOTE UE IN SIDELINK MODE 1 PCT/US2024/016896 | J31: GURGAON | K31: 45834 | L31: 44985 | M31: 45840 | O31: 45840 | P31: Yeshwanth Thirunagari | Q31: Sarla Bhavani | R31: RFE FILED
A32: 31 | B32: IP88404 | C32: 202517063043 | D32: QUALCOMM INCORPORATED | E32: 2301194IN | F32: United States Of America | G32: QUALCOMM INCORPORATED | H32: ASYMMETRIC CONFIDENCE LEVEL FOR PREDICTIVE BEAM MANAGEMENT PCT/CN2023/076370 | J32: GURGAON | K32: 45839 | L32: 45840 | M32: 45840 | O32: 45840 | P32: Sanjit Kumar | Q32: Anand Yenurkar | R32: RFE FILED
A33: 32 | B33: IP87908 | C33: 202547063118 | D33: BOZICEVIC FIELD & FRANCIS LLP | E33: BERK-480IN | F33: United States Of America | G33: THE REGENTS OF THE UNIVERSITY OF CALIFORNIA | H33: INHIBITORY NUCLEIC ACIDS AND METHODS OF USE THEREOF PCT/US2023/082556 | J33: GURGAON | K33: 45814 | L33: 44902 | M33: 45840 | O33: 45840 | P33: Sneha Menon | Q33: Renuka R | R33: RFE FILED
A34: 33 | B34: IP88173 | C34: 202517063014 | D34: YOU ME PATENT & LAW FIRM | E34: OPP20244104IN | F34: Korea | G34: LG ENERGY SOLUTION, LTD. | H34: ENERGY STORAGE SYSTEM, AND PROTECTION DEVICE AND PROTECTION METHOD THEREOF PCT/KR2024/011757 | J34: GURGAON | K34: 45827 | L34: 45252 | M34: 45840 | O34: 45840 | P34: Vivek Atwal | Q34: Umesh Sharma | R34: RFE FILED
A35: 34 | B35: IP87646 | C35: 202517063099 | D35: SELIGSOHN GABRIELI BENSHAFRUT & CO. | E35: SOL-P-80950WOIN | F35: Israel | G35: SOLUTUM TECHNOLOGIES LTD | H35: BIODEGRADABLE AND BARRIER PVOH-BASED MATERIALS AND PRODUCTS MADE THEREFROM PCT/IL2023/051310 | J35: GURGAON | K35: 45803 | L35: 44922 | M35: 45840 | O35: 45840 | P35: Yameeni Sarothia | Q35: Arub Mistree | R35: RFE FILED
A36: 35 | B36: IP87971 | C36: 202517063177 | D36: CISCO TECHNOLOGY, INC. | E36: C/P/1034640/IN/PCT/1 | F36: United States Of America | G36: CISCO TECHNOLOGY, INC. | H36: SOFTWARE-DEFINED DEVICE TRACKING IN NETWORK FABRICS PCT/US2023/082841 | J36: GURGAON | K36: 45819 | L36: 44902 | M36: 45840 | O36: 45840 | P36: Hrudya Ravula | Q36: Prema Latha | R36: RFE FILED
A37: 36 | B37: IP88291 | C37: 202517063150 | D37: DONALDSON COMPANY INC | E37: 00011014-IN01 | F37: United States Of America | G37: DONALDSON COMPANY INC | H37: FILTER ELEMENTS, RELATED FILTER ASSEMBLY AND FILTER PACKAGE PCT/US2024/015821 | J37: GURGAON | K37: 45833 | L37: 44971 | M37: 45840 | O37: 45840 | P37: Himanshu Singh | Q37: Komal | R37: RFE FILED
A38: 37 | B38: IP86453 | C38: 202541063217 | D38: TITAN COMPANY LIMITED | E38: PLEASE PROVIDE | F38: India | G38: TITAN COMPANY LIMITED | H38: A TIMEPIECE | I38: Complete Filed | J38: GURGAON | K38: 45736 | L38: 45840 | M38: 45840 | O38: 45840 | P38: Alok Hegde | Q38: Navya N | R38: RFE FILED
A39: 38 | B39: IP87164 | C39: 202511063152 | D39: ICAR-CENTRAL SHEEP & WOOL RESEARCH INSTITUTE | E39: PLEASE PROVIDE | F39: India | G39: INDIAN COUNCIL OF AGRICULTURAL RESEARCH | H39: A WOOL FIBRE BLEND, ARTICLES AND METHODS THEREOF | I39: Provisional | J39: GURGAON | K39: 45775 | L39: 45840 | M39: 45840 | N39: 46785 | P39: Niharika Singh | Q39: Vandana . | R39: PROVISIONAL FILED
A40: 39 | B40: IP86564 | C40: 202517063157 | D40: KIP PATENT LAW FIRM | E40: 24PCTIN985 | F40: Korea | G40: LG ENERGY SOLUTION, LTD. | H40: ANODE, ANODE DAM COATING COMPOSITION, AND LITHIUM SECONDARY BATTERY PCT/KR2024/014546 | J40: GURGAON | K40: 45741 | L40: 45195 | M40: 45840 | O40: 45841 | P40: Toral Chauhan | Q40: Renu Rani | R40: RFE FILED
...
